INFO:werkzeug: * Debugger PIN: 136-602-962
(617) wsgi starting up on http://0.0.0.0:5000
(617) accepted ('172.31.128.91', 33756)
Traceback (most recent call last):
  File "/home/runner/workspace/.pythonlibs/lib/python3.11/site-packages/werkzeug/middleware/proxy_fix.py", line 182, in __call__
    return self.app(environ, start_response)
           ^^^^^^^^^^^^^^^^^^^^^^^^^^^^^^^^^
  File "/home/runner/workspace/.pythonlibs/lib/python3.11/site-packages/flask/app.py", line 1458, in wsgi_app
    response = self.handle_exception(e)
               ^^^^^^^^^^^^^^^^^^^^^^^^
  File "/home/runner/workspace/.pythonlibs/lib/python3.11/site-packages/flask/app.py", line 1455, in wsgi_app
    response = self.full_dispatch_request()
               ^^^^^^^^^^^^^^^^^^^^^^^^^^^^
  File "/home/runner/workspace/.pythonlibs/lib/python3.11/site-packages/flask/app.py", line 869, in full_dispatch_request
    rv = self.handle_user_exception(e)
         ^^^^^^^^^^^^^^^^^^^^^^^^^^^^^
  File "/home/runner/workspace/.pythonlibs/lib/python3.11/site-packages/flask/app.py", line 867, in full_dispatch_request
    rv = self.dispatch_request()
         ^^^^^^^^^^^^^^^^^^^^^^^
  File "/home/runner/workspace/.pythonlibs/lib/python3.11/site-packages/flask/app.py", line 852, in dispatch_request
    return self.ensure_sync(self.view_functions[rule.endpoint])(**view_args)
           ^^^^^^^^^^^^^^^^^^^^^^^^^^^^^^^^^^^^^^^^^^^^^^^^^^^^^^^^^^^^^^^^^
  File "/home/runner/workspace/routes/__init__.py", line 16, in index
    return render_template('index.html')
           ^^^^^^^^^^^^^^^^^^^^^^^^^^^^^
  File "/home/runner/workspace/.pythonlibs/lib/python3.11/site-packages/flask/templating.py", line 152, in render_template
    return _render(app, template, context)
           ^^^^^^^^^^^^^^^^^^^^^^^^^^^^^^^
  File "/home/runner/workspace/.pythonlibs/lib/python3.11/site-packages/flask/templating.py", line 133, in _render
    rv = template.render(context)
         ^^^^^^^^^^^^^^^^^^^^^^^^
  File "/home/runner/workspace/.pythonlibs/lib/python3.11/site-packages/jinja2/environment.py", line 1301, in render
    self.environment.handle_exception()
  File "/home/runner/workspace/.pythonlibs/lib/python3.11/site-packages/jinja2/environment.py", line 936, in handle_exception
    raise rewrite_traceback_stack(source=source)
  File "/home/runner/workspace/templates/index.html", line 1, in top-level template code
    {% extends "layout.html" %}
  File "/home/runner/workspace/.pythonlibs/lib/python3.11/site-packages/jinja2/environment.py", line 936, in handle_exception
    raise rewrite_traceback_stack(source=source)
  File "/home/runner/workspace/templates/layout.html", line 212, in template
    {% block content %}{% endblock %}
jinja2.exceptions.TemplateAssertionError: block 'content' defined twice
197.54.191.26,10.81.0.156,172.31.128.91 - - [05/May/2025 14:58:06] "GET / HTTP/1.1" 500 26854 0.031261
197.54.191.26,10.81.8.102,172.31.128.91 - - [05/May/2025 14:58:07] "GET /?__debugger__=yes&cmd=resource&f=style.css HTTP/1.1" 304 192 0.007138
(617) accepted ('172.31.128.91', 33760)
197.54.191.26,10.81.0.156,172.31.128.91 - - [05/May/2025 14:58:07] "GET /?__debugger__=yes&cmd=resource&f=debugger.js HTTP/1.1" 304 195 0.001564
(617) accepted ('172.31.128.91', 33772)
197.54.191.26,10.81.8.102,172.31.128.91 - - [05/May/2025 14:58:08] "GET /?__debugger__=yes&cmd=resource&f=console.png HTTP/1.1" 304 195 0.037444
